Workbook

Sheet Master
A1: Months | B1: Dealer Code | C1: Firm Name | D1: Dine-Out/Salon/Spa/ Photoshoot/Concert | E1: RM | F1: PAYMENT SPOC | G1: Amount Paid | H1: Billing Amount | I1: STORY
A2: Apr`26 | B2: CIN0207 | C2: Indira Enterprisers | D2: Salon | E2: Ravinder | F2: Himanshu | G2: 12600 | H2: 12600 | I2: 0
A3: Apr`26 | B3: CNE0666 | C3: Newtec Industries | D3: Salon | E3: Ravinder | F3: Himanshu | G3: 11000 | H3: 11000 | I3: 0
A4: Apr`26 | B4: CRA1049 | C4: Rainbow Lights | D4: Salon | E4: Simran | F4: Supriya | G4: 9603 | H4: 9803 | I4: 200
A5: Apr`26 | B5: CIS0059 | C5: Ishan Corporation | D5: Dine-Out | E5: Ravinder | F5: Himanshu | G5: 4718 | H5: 5418 | I5: 700
A6: Apr`26 | B6: CSU1679 | C6: SUN SPARKLE ENERGY | D6: Spa | E6: Ravinder | F6: Himanshu | G6: 2000 | H6: 4000 | I6: 2000
A7: Apr`26 | B7: CRE0045 | C7: Relax Agencies | D7: Dine-Out | E7: Simran | F7: Parmeet | G7: 9558 | H7: 9558 | I7: 0
A8: Apr`26 | B8: CNA0110 | C8: Navratan Electric Co. | D8: Dine-Out | E8: Simran | F8: Simran | G8: 5192 | H8: 7792 | I8: 2600
A9: Apr`26 | B9: CBI0452 | C9: Bindra Electric Company | D9: Salon | E9: Simran | F9: Supriya | G9: 8702 | H9: 9745 | I9: 1043
A10: Apr`26 | B10: CSR6389 | C10: Vishnu Enterprises | D10: Dine-Out | E10: Simran | F10: Parmeet | G10: 3900 | H10: 4900 | I10: 1000
A11: Apr`26 | B11: CBA2341 | C11: Bansal Traders | D11: Salon | E11: Simran | F11: Supriya | G11: 10000 | H11: 10000 | I11: 0
A12: Apr`26 | B12: CPO0268 | C12: Pooja Electricals | D12: Dine-Out | E12: Simran | F12: Parmeet | G12: 5535 | H12: 5935 | I12: 400
A13: Apr`26 | B13: CPR0279 | C13: Prem Electricals | D13: Dine-Out | E13: Simran | F13: Parmeet | G13: 6486 | H13: 7549 | I13: 1063
... A295: Apr`26 | B295: CJY0055 | C295: Jyoti Electricals | D295: Photoshoot | E295: Simran | F295: Simran | G295: 20000 | H295: 21500 | I295: 1500
A296: May`26 | B296: CAM0375 | C296: Ambica Electricals | D296: Spa | E296: Simran | F296: Simran | G296: 10000 | H296: 10000 | I296: =H296-G296 -> 0
A297: May`26 | B297: CBR0195 | C297: Branz Hexa India Private Limited | D297: Salon | E297: Simran | F297: Himanshu | G297: 8600 | H297: 9600 | I297: =H297-G297 -> 1000
A298: May`26 | B298: CRA1613 | C298: Rakhi Traders | D298: Dine-Out | E298: Parsun | F298: Parsun | G298: 4076 | H298: 6776 | I298: =H298-G298 -> 2700
A299: May`26 | B299: CSA2472 | C299: SAFFRON SOLAR SYSTEMS | D299: Dine-Out | E299: Aayushi | F299: Himanshu | G299: 2223.9 | H299: 4223 | I299: =H299-G299 -> 1999.1
A300: May`26 | B300: CJJ0024 | C300: J J Traders | D300: Dine-Out | E300: Aayushi | F300: Aayushi | G300: 8491.25 | H300: 9491 | I300: =H300-G300 -> 999.75
A301: May`26 | B301: CAD0630 | C301: Adithi Business Solutions | D301: Dine-Out | E301: Aayushi | F301: Parmeet | G301: 9665 | H301: 9665 | I301: =H301-G301 -> 0
A302: May`26 | B302: CHI0083 | C302: Hindustan Electric Corporation | D302: Dine-Out | E302: Ravinder | F302: Himanshu | G302: 5154 | H302: 5154 | I302: =H302-G302 -> 0
A303: May`26 | B303: CNE1037 | C303: Neeraj Traders | D303: Dine-Out | E303: Aayushi | F303: Himanshu | G303: 3938 | H303: 5938 | I303: =H303-G303 -> 2000
A304: May`26 | B304: CRA0677 | C304: Radiant Hardware | D304: Salon | E304: Simran | F304: Himanshu | G304: 8350 | H304: 9350 | I304: =H304-G304 -> 1000
A305: May`26 | B305: CUN0042 | C305: Universal Electricals | D305: Spa | E305: Aayushi | F305: Himanshu | G305: 8280 | H305: 9485 | I305: =H305-G305 -> 1205
A306: May`26 | B306: CMM0025 | C306: M.M Traders | D306: Dine-Out | E306: Aayushi | F306: Parmeet | G306: 5754 | H306: 7754 | I306: =H306-G306 -> 2000
A307: May`26 | B307: CLI0300 | C307: Live Wire Tech Services Llp | D307: Dine-Out | E307: Aayushi | F307: Parmeet | G307: =8566+75 -> 8641 | H307: 10000 | I307: =H307-G307 -> 1359
A308: May`26 | B308: CKR0436 | C308: Krish Enterprisess | D308: Spa | E308: Ravinder | F308: Bharti | G308: 7000 | H308: 8000 | I308: =H308-G308 -> 1000
A309: May`26 | B309: CJI0245 | C309: JIBIN ELECTRICALS & HOME APPLIANCES | D309: Dine-Out | E309: Aayushi | F309: Bharti | G309: 4336.5 | H309: 6336 | I309: =H309-G309 -> 1999.5
A310: May`26 | B310: CEM0125 | C310: EMAC AUTOMATION SOLUTIONS INDIA PRI | D310: Dine-Out | E310: Aayushi | F310: Himanshu | G310: =3000+3088 -> 6088 | H310: 8088 | I310: =H310-G310 -> 2000
A311: May`26 | B311: CSH3891 | C311: Shree Ganesh Traders | D311: Dine-Out | E311: Parsun | F311: Parsun | G311: 4314 | H311: 7714 | I311: =H311-G311 -> 3400
A312: May`26 | B312: CSH0701 | C312: Shivam Electricals | D312: Dine-Out | E312: Simran | F312: Bharti | G312: 4580.59 | H312: 5580 | I312: =H312-G312 -> 999.41
A313: May`26 | B313: CSU0821 | C313: Success Enterprises | D313: Dine-Out | E313: Aayushi | F313: Bharti | G313: 9894 | H313: 9894 | I313: =H313-G313 -> 0
A314: May`26 | B314: CPI0176 | C314: Pipeco | D314: Dine-Out | E314: Parsun | F314: Parsun | G314: =6750+6053 -> 12803 | H314: 10000 | I314: =H314-G314 -> -2803
A315: May`26 | B315: CSP0007 | C315: S P Electrical Industries | D315: Salon | E315: Parsun | F315: Bharti | G315: 10000 | H315: 10000 | I315: =H315-G315 -> 0
A316: May`26 | B316: CEL0179 | C316: Elmec | D316: Dine-Out | E316: Simran | F316: Simran | G316: =5000+12000 -> 17000 | H316: 17000 | I316: =H316-G316 -> 0
A317: May`26 | B317: CNE0588 | C317: New Kable Point | D317: Dine-Out | E317: Aayushi | F317: Aayushi | G317: 3301 | H317: 5801 | I317: =H317-G317 -> 2500
A318: May`26 | B318: CPA0760 | C318: Patna Machinery Stores | D318: Dine-Out | E318: Aayushi | F318: Aayushi | G318: 2350 | H318: 4350 | I318: =H318-G318 -> 2000
A319: May`26 | B319: CIM0048 | C319: Impex Distribution Llp | D319: Dine-Out | E319: Aayushi | F319: Himanshu | G319: =8420+2731+1163 -> 12314 | H319: 12314 | I319: =H319-G319 -> 0
A320: May`26 | B320: CLI0035 | C320: Light Centre | D320: Salon | E320: Parsun | F320: Himanshu | G320: 9200 | H320: 9950 | I320: =H320-G320 -> 750
A321: May`26 | B321: CGA0584 | C321: Gandhi Electric Stores | D321: Dine-Out | E321: Simran | F321: Parmeet | G321: =8466+1361 -> 9827 | H321: 9827 | I321: =H321-G321 -> 0
...

Sheet RAW_Summary
A3: Sum of STORY | B3: Months
A4: RM | B4: Apr`26 | C4: Aug`26 | D4: Jul`26 | E4: Jun`26 | F4: May`26 | G4: Grand Total
A5: Aayushi | B5: 57957.81 | C5: 85412 | D5: 35861.54 | E5: 59742 | F5: 50671.95 | G5: 289645.3
A6: Himanshu | B6: 1300 | G6: 1300
A7: Parsun | B7: 74109.26 | C7: 51379 | D7: 50524 | E7: 56826.3 | F7: 46302.3 | G7: 279140.86
A8: Ravinder | B8: 50783.06 | C8: 36973.42 | D8: 58951.312 | E8: 42325.87 | F8: 25439.01 | G8: 214472.67
A9: Simran | B9: 65958.5 | C9: 49510.62 | D9: 66556.54 | E9: 86330 | F9: 51401.27 | G9: 319756.93
A10: Grand Total | B10: 250108.63 | C10: 223275.04 | D10: 211893.39 | E10: 245224.17 | F10: 173814.53 | G10: 1104315.8
A17: Sum of STORY | B17: Months
A18: PAYMENT SPOC | B18: Apr`26 | C18: Aug`26 | D18: Jul`26 | E18: Jun`26 | F18: May`26 | G18: Grand Total
A19: Aayushi | B19: 21724 | C19: 61346 | D19: 41141.54 | E19: 22742 | F19: 18199.27 | G19: 165152.81
A20: Bharti | B20: 45807.6 | E20: 24019.87 | F20: 25049.45 | G20: 94876.92
A21: Himanshu | B21: 57765.2 | C21: 9412 | D21: 7528.312 | E21: 54950 | F21: 25903.64 | G21: 155559.15
A22: Parmeet | B22: 35310.95 | E22: 42990 | F22: 16532.36 | G22: 94833.31
A23: Parsun | B23: 37646.88 | C23: 47179 | D23: 50524 | E23: 51726.3 | F23: 38762.3 | G23: 225838.48
A24: Ravinder | B24: 12162 | C24: 12362 | D24: 48443 | E24: 10796 | F24: 16239.01 | G24: 100002.01
A25: Rishabh | B25: 1933 | G25: 1933
A26: Simran | B26: 20287 | C26: 38144.62 | D26: 62256.54 | E26: 38000 | F26: 33128.5 | G26: 191816.66
A27: Supriya | B27: 17472 | G27: 17472
A28: Vikrant | C28: 54831.42 | D28: 2000 | G28: 56831.42
A29: Grand Total | B29: 250108.63 | C29: 223275.04 | D29: 211893.39 | E29: 245224.17 | F29: 173814.53 | G29: 1104315.8

Sheet Summary
A2: PAYMENT SPOC Wise Summary | J2: RM Wise Summary
A5: Name | B5: Apr`26 | C5: May`26 | D5: Jun`26 | E5: Jul`26 | F5: Aug`26 | G5: Grand Total | J5: Name | K5: Apr`26 | L5: May`26 | M5: Jun`26 | N5: Jul`26 | O5: Aug`26 | P5: Grand Total
A6: Aayushi | B6: {=_xlfn.XLOOKUP(B5,RAW_Summary!18:18,RAW_Summary!19:29)} -> 21724 | C6: {=_xlfn.XLOOKUP(C5,RAW_Summary!18:18,RAW_Summary!19:29)} -> 18199.27 | D6: {=_xlfn.XLOOKUP(D5,RAW_Summary!18:18,RAW_Summary!19:29)} -> 22742 | E6: {=_xlfn.XLOOKUP(E5,RAW_Summary!18:18,RAW_Summary!19:29)} -> 41141.54 | F6: {=_xlfn.XLOOKUP(F5,RAW_Summary!18:18,RAW_Summary!19:29)} -> 61346 | G6: {=_xlfn.XLOOKUP(G5,RAW_Summary!18:18,RAW_Summary!19:29)} -> 165152.81 | J6: Aayushi | K6: {=_xlfn.XLOOKUP(K5,RAW_Summary!4:4,RAW_Summary!5:10)} -> 57957.81 | L6: {=_xlfn.XLOOKUP(L5,RAW_Summary!4:4,RAW_Summary!5:10)} -> 50671.95 | M6: {=_xlfn.XLOOKUP(M5,RAW_Summary!4:4,RAW_Summary!5:10)} -> 59742 | N6: {=_xlfn.XLOOKUP(N5,RAW_Summary!4:4,RAW_Summary!5:10)} -> 35861.54 | O6: {=_xlfn.XLOOKUP(O5,RAW_Summary!4:4,RAW_Summary!5:10)} -> 85412 | P6: {=_xlfn.XLOOKUP(P5,RAW_Summary!4:4,RAW_Summary!5:10)} -> 289645.3
A7: Bharti | B7: 45807.6 | C7: 25049.45 | D7: 24019.87 | E7: 0 | F7: 0 | G7: 94876.92 | J7: Himanshu | K7: 1300 | L7: 0 | M7: 0 | N7: 0 | O7: 0 | P7: 1300
A8: Himanshu | B8: 57765.2 | C8: 25903.64 | D8: 54950 | E8: 7528.312 | F8: 9412 | G8: 155559.15 | J8: Parsun | K8: 74109.26 | L8: 46302.3 | M8: 56826.3 | N8: 50524 | O8: 51379 | P8: 279140.86
A9: Parmeet | B9: 35310.95 | C9: 16532.36 | D9: 42990 | E9: 0 | F9: 0 | G9: 94833.31 | J9: Ravinder | K9: 50783.06 | L9: 25439.01 | M9: 42325.87 | N9: 58951.312 | O9: 36973.42 | P9: 214472.67
A10: Parsun | B10: 37646.88 | C10: 38762.3 | D10: 51726.3 | E10: 50524 | F10: 47179 | G10: 225838.48 | J10: Simran | K10: 65958.5 | L10: 51401.27 | M10: 86330 | N10: 66556.54 | O10: 49510.62 | P10: 319756.93
A11: Ravinder | B11: 12162 | C11: 16239.01 | D11: 10796 | E11: 48443 | F11: 12362 | G11: 100002.01 | J11: Grand Total | K11: 250108.63 | L11: 173814.53 | M11: 245224.17 | N11: 211893.39 | O11: 223275.04 | P11: 1104315.8
A12: Rishabh | B12: 1933 | C12: 0 | D12: 0 | E12: 0 | F12: 0 | G12: 1933
A13: Simran | B13: 20287 | C13: 33128.5 | D13: 38000 | E13: 62256.54 | F13: 38144.62 | G13: 191816.66
A14: Supriya | B14: 17472 | C14: 0 | D14: 0 | E14: 0 | F14: 0 | G14: 17472
A15: Vikrant | B15: 0 | C15: 0 | D15: 0 | E15: 2000 | F15: 54831.42 | G15: 56831.42
A16: Grand Total | B16: 250108.63 | C16: 173814.53 | D16: 245224.17 | E16: 211893.39 | F16: 223275.04 | G16: 1104315.8
